Workbook

Sheet DEFINE
B2: DEFINE
B3: Suppliers | C3: Inputs | D3: Process | E3: Outputs | F3: Customers
B4: Prefeitura | C4: Infraestrutura turística | D4: Atração de visitantes (divulgação, reputação e acessibilidade) | E4: Desenvolvimento econômico | F4: Moradores
B5: Setor privado local | C5: Marketing e divulgação da cidade | D5: Recepção e permanência (hospedagem, segurança, serviços e pontos turísticos) | E5: Desenvolvimento turístico | F5: Setor privado
C6: Investimento público | D6: Gasto do visitante na cidade (comércio, alimentação, lazer) | E6: qualidade de vida | F6: Prefeitura
C7: Segurança pública | D7: Geração de emprego e renda local | F7: Turistas
C8: Investimento privado | D8: Arrecadação de impostos sobre essas atividades
B10: VOC (Voice of Customer) | G10: Indicador | H10: Pergunta
B11: Produto | C11: Direcionadores | D11: Variável | E11: Indicadores | G11: População | H11: Crescimento acima da média regional?
B12: Maior qualidade de vida | C12: Menos roubos e furtos | D12: Segurança pública | E12: furtos e roubos por 100k/hab | G12: Homicídio doloso | H12: O crescimento foi contínuo?
C13: Menos homicídios | D13: Segurança pública | E13: homicídios dolosos por 100k/hab | G13: Furtos e Roubos | H13: O crescimento foi contínuo?
C14: Melhoria dos pontos turísticos | D14: Turismo | E14: Empregos gerados no setor de turismo | G14: Empregos no setor de turismo | H14: O crescimento foi abaixo da média de Cabo Frio?
C15: Melhoria da educação e saúde | D15: Desenvolvimento humano | E15: IDH | G15: IDH | H15: O crescimento foi contínuo?
C16: Desenvolvimento das orlas | D16: Turismo | E16: Arrecadação total | G16: Arrecadação | H16: O crescimento foi proporcional à população?
C17: Mais empregos | D17: Desenvolvimento econômico | E17: PIB per capita | G17: PIB per capita | H17: Crescimento foi lento?

Sheet MEASURE & FONTES
A1: FONTES DE DADOS E NOTAS METODOLÓGICAS — Projeto Rio das Ostras
A3: TABELA DE FONTES
A4: Indicador | B4: Fonte | C4: Período | D4: URL / Acesso | E4: Notas Metodológicas | F4: Limitações
A5: População | B5: IBGE — Censos Demográficos + Estimativas Populacionais anuais (DOU) | C5: 1996–2025 | D5: ibge.gov.br/estatisticas/sociais/populacao/ 9103-estimativas-de-populacao.html | E5: PIB per capita calculado como: PIB total IBGE ÷ população do respectivo ano. Censos: 2000, 2010, 2022. Estimativas intermediárias publicadas anualmente no DOU. | F5: Ano 2023 ausente nas estimativas oficiais (IBGE não publicou estimativa municipal pós-Censo 2022). Valor de 2023 obtido por interpolação linear entre 2022 e 2024.
A6: PIB per Capita | B6: IBGE — Sistema de Contas Regionais Tabela 5938 (PIB municipal a preços correntes) | C6: 2010–2023 | D6: sidra.ibge.gov.br/tabela/5938 | E6: PIB disponibilizado em R$ mil. Convertido para R$ multiplicando por 1.000. PIB per capita = PIB total ÷ população do ano. Valores nominais (não deflacionados pelo IPCA). | F6: Valores nominais não permitem comparação direta entre anos sem aplicação de deflator. Comparação entre municípios no mesmo ano é válida.
A7: Violência (Roubos, Furtos, Homicídio Doloso) | B7: ISP-RJ — Instituto de Segurança Pública do Rio de Janeiro Base Municipal Mensal | C7: 2014–2025 | D7: ispdados.rj.gov.br/Arquivos/ BaseMunicipioMensal.csv | E7: Dados mensais agregados por ano. Taxa por 100k hab = (ocorrências ÷ população) × 100.000. Região dos Lagos: soma de 10 municípios (Araruama, Búzios, Arraial do Cabo, Cabo Frio, Casimiro de Abreu, Iguaba Grande, Rio das Ostras, São Pedro da Aldeia, Saquarema, Silva Jardim). | F7: Ano 2026 excluído (ano incompleto). Dados refletem ocorrências registradas — subnotificação não mensurável.
A8: IDH Municipal (IDHM) | B8: Atlas do Desenvolvimento Humano no Brasil — PNUD, IPEA e Fundação João Pinheiro | C8: 2000, 2010, 2021 | D8: atlasbrasil.org.br | E8: 2000 e 2010 (Censos), 2021 (PNAD Contínua) | F8: Apenas 3 pontos temporais disponíveis. Não permite análise de tendência densa — utilizado como comparação pontual entre municípios; os subíndices de Cabo Frio e Macaé para 2021 foram estimados com base nos valores gerais e proporções históricas
A9: Empregos Formais no Turismo | B9: MTE — RAIS (Relação Anual de Informações Sociais) via Base dos Dados (basedosdados.org) | C9: 2010–2021 | D9: basedosdados.org Tabela: br_me_rais.microdados_vinculos | E9: CNAEs incluídos: 5510 (Hotéis e similares) 5590 (Outros alojamentos / pousadas) 7911 (Agências de viagem) 7912 (Operadoras turísticas) 7990 (Serviços de reservas) Vínculos ativos em 31/dez de cada ano. | F9: Série disponível até 2021 na base utilizada. Cabo Frio: queries iniciais retornavam zero por uso de código IBGE incorreto (3300951). Corrigido para 3300704.
A10: Total de Empregos Formais | B10: MTE — RAIS (Relação Anual de Informações Sociais) via Base dos Dados (basedosdados.org) | C10: 2010–2021 | D10: basedosdados.org Tabela: br_me_rais.microdados_vinculos | E10: Total de vínculos ativos em 31/dez de cada ano, todos os CNAEs. Permite calcular participação do turismo no total de empregos formais. | F10: Cobre apenas empregos com carteira assinada (CLT). Não inclui MEI, autônomos, informais ou servidores públicos estatutários.
A11: Arrecadação Municipal | B11: SICONFI — Sistema de Informações Contábeis e Fiscais do Setor Público (Tesouro Nacional) | C11: 2013–2024 | D11: siconfi.tesouro.fazenda.gov.br | E11: Receitas e despesas orçamentárias brutas. Receita per capita = receita total ÷ população do ano. Inclui royalties, transferências federais/estaduais e receita tributária própria (ISS, IPTU, ITBI). | F11: Não é possível isolar receita de ISS do setor de turismo especificamente — dados fiscais municipais não são desagregados por setor econômico nas bases públicas; Macaé 2014: dado ausente na base original. Valor estimado como média de 2013 e 2015.
A12: Interesse Digital (Google Trends) | B12: Google Trends | C12: 2004–2006 | D12: trends.google.com | E12: Termos pesquisados: "hotel Rio das Ostras" + "pousada Rio das Ostras" "hotel Cabo Frio" + "pousada Cabo Frio" Índice relativo 0–100 (100 = pico histórico da série). Indicador anual = soma dos valores mensais do índice (0-100) de cada termo, agregados por cidade e ano." | F12: Índice relativo, não volume absoluto de buscas. Série disponível apenas a partir de jun/2021 na exportação realizada. Dados anteriores a 2021 não foram coletados.
A14: NOTAS GERAIS
A15: Municípios analisados | B15: Rio das Ostras (foco), Cabo Frio (comparação primária), Macaé (comparação secundária), Região dos Lagos (benchmark regional)
A16: Códigos IBGE | B16: Rio das Ostras: 3304524 | Cabo Frio: 3300704 | Macaé: 3302403
A17: Valores monetários | B17: Todos os valores monetários estão em R$ correntes (nominais). Não foi aplicado deflator. Comparações entre anos devem considerar inflação do período.
A18: Interpolações | B18: Anos sem dado oficial foram estimados por interpolação linear entre os anchor points mais próximos do IBGE. Valores interpolados estão identificados nas respectivas abas.
A19: Metodologia do projeto | B19: Projeto estruturado segundo o framework DMAIC (Define, Measure, Analyze, Improve, Control) do Lean Six Sigma.
A20: Correlações no Analyze | B20: os coeficientes de Pearson apresentados foram calculados com n = 8 a 12 observações anuais. Amostras pequenas aumentam a sensibilidade do coeficiente a valores extremos, e a maioria das séries compartilha uma tendência declinante no período 2013-2021, o que pode inflar correlações mesmo sem relação causal direta. Os valores devem ser interpretados como indicativos de associação, e não como prova de causalidade.

Sheet População
B3: CRESCIMENTO POPULACIONAL
B4: Ano | C4: Rio das Ostras | D4: Cabo Frio | E4: Macaé
B5: =ROW() - ROW($B$4) + 2005 -> 2006 | C5: 49868 | D5: 162467 | E5: 173762
B6: =ROW() - ROW($B$4) + 2005 -> 2007 | C6: 74750 | D6: 168407 | E6: 180646
B7: =ROW() - ROW($B$4) + 2005 -> 2008 | C7: 91085 | D7: 174347 | E7: 187529
B8: =ROW() - ROW($B$4) + 2005 -> 2009 | C8: 96622 | D8: 180287 | E8: 194413
B9: =ROW() - ROW($B$4) + 2005 -> 2010 | C9: 105676 | D9: 186227 | E9: 206728
B10: =ROW() - ROW($B$4) + 2005 -> 2011 | C10: 110992 | D10: 190765 | E10: 212341
B11: =ROW() - ROW($B$4) + 2005 -> 2012 | C11: 116134 | D11: 195302 | E11: 217954
B12: =ROW() - ROW($B$4) + 2005 -> 2013 | C12: 122196 | D12: 199840 | E12: 223567
B13: =ROW() - ROW($B$4) + 2005 -> 2014 | C13: 127171 | D13: 204378 | E13: 229180
B14: =ROW() - ROW($B$4) + 2005 -> 2015 | C14: 131976 | D14: 208915 | E14: 234792
B15: =ROW() - ROW($B$4) + 2005 -> 2016 | C15: 136626 | D15: 213453 | E15: 240405
B16: =ROW() - ROW($B$4) + 2005 -> 2017 | C16: 141117 | D16: 217990 | E16: 246018
... B24: =ROW() - ROW($B$4) + 2005 -> 2025 | C24: 168455 | D24: 238438 | E24: 264439
B25: Total | C25: =(C24-C5)/C5 -> 2.378018 | D25: =(D24-D5)/D5 -> 0.46760881 | E25: =(E24-E5)/E5 -> 0.52184597

Sheet Violência
A2: ROUBOS | F2: FURTOS | K2: HOMICÍDIO DOLOSO
A3: Ano | B3: Rio das Ostras | C3: Cabo Frio | D3: Região dos Lagos | F3: Ano | G3: Rio das Ostras | H3: Cabo Frio | I3: Região dos Lagos | K3: Ano | L3: Rio das Ostras | M3: Cabo Frio | N3: Região dos Lagos
A4: 2014 | B4: 857 | C4: 929 | D4: 2969 | F4: 2014 | G4: 1811 | H4: 2675 | I4: 9228 | K4: 2014 | L4: 44 | M4: 146 | N4: 333
A5: 2015 | B5: 740 | C5: 716 | D5: 2569 | F5: 2015 | G5: 1798 | H5: 2290 | I5: 8627 | K5: 2015 | L5: 50 | M5: 129 | N5: 323
A6: 2016 | B6: 1094 | C6: 952 | D6: 3672 | F6: 2016 | G6: 1535 | H6: 1803 | I6: 7679 | K6: 2016 | L6: 80 | M6: 125 | N6: 420
A7: 2017 | B7: 918 | C7: 1049 | D7: 3865 | F7: 2017 | G7: 1334 | H7: 1725 | I7: 6873 | K7: 2017 | L7: 62 | M7: 118 | N7: 399
A8: 2018 | B8: 1138 | C8: 960 | D8: 3956 | F8: 2018 | G8: 1294 | H8: 1442 | I8: 6832 | K8: 2018 | L8: 61 | M8: 107 | N8: 392
A9: 2019 | B9: 846 | C9: 1032 | D9: 3663 | F9: 2019 | G9: 1538 | H9: 1880 | I9: 7899 | K9: 2019 | L9: 32 | M9: 95 | N9: 279
A10: 2020 | B10: 694 | C10: 628 | D10: 2393 | F10: 2020 | G10: 1210 | H10: 1547 | I10: 5817 | K10: 2020 | L10: 65 | M10: 88 | N10: 322
A11: 2021 | B11: 567 | C11: 545 | D11: 2174 | F11: 2021 | G11: 1253 | H11: 1371 | I11: 5588 | K11: 2021 | L11: 63 | M11: 81 | N11: 312
A12: 2022 | B12: 462 | C12: 497 | D12: 1881 | F12: 2022 | G12: 1296 | H12: 2163 | I12: 7170 | K12: 2022 | L12: 32 | M12: 77 | N12: 247
A13: 2023 | B13: 261 | C13: 383 | D13: 1273 | F13: 2023 | G13: 1309 | H13: 2237 | I13: 7090 | K13: 2023 | L13: 25 | M13: 65 | N13: 258
A14: 2024 | B14: 156 | C14: 391 | D14: 1157 | F14: 2024 | G14: 1210 | H14: 2174 | I14: 7399 | K14: 2024 | L14: 22 | M14: 97 | N14: 266
A15: 2025 | B15: 146 | C15: 337 | D15: 1083 | F15: 2025 | G15: 1197 | H15: 2340 | I15: 7436 | K15: 2025 | L15: 20 | M15: 63 | N15: 225
D17: /100k habitantes
D18: Rio das Ostras | G18: Cabo Frio | J18: Região dos Lagos
C19: Ano | D19: Roubos_RO | E19: Furtos_RO | F19: HD_RO | G19: Roubos_CF | H19: Furtos_CF | I19: HD_CF | J19: Roubos_RL | K19: Furtos_RL | L19: HD_RL
C20: 2014 | D20: 681.1 | E20: 1439.2 | F20: 35 | G20: 454.5 | H20: 1308.8 | I20: 71.4 | J20: 380.5 | K20: 1182.5 | L20: 42.7
C21: 2015 | D21: 565.4 | E21: 1373.9 | F21: 38.2 | G21: 342.7 | H21: 1096.1 | I21: 61.7 | J21: 321.3 | K21: 1079 | L21: 40.4
C22: 2016 | D22: 804.9 | E22: 1129.4 | F22: 58.9 | G22: 446 | H22: 844.7 | I22: 58.6 | J22: 448.5 | K22: 938 | L22: 51.3
C23: 2017 | D23: 651.3 | E23: 946.4 | F23: 44 | G23: 481.2 | H23: 791.3 | I23: 54.1 | J23: 461.3 | K23: 820.3 | L23: 47.6
C24: 2018 | D24: 779.5 | E24: 886.4 | F24: 41.8 | G24: 431.4 | H24: 648 | I24: 48.1 | J24: 461.6 | K24: 797.2 | L24: 45.7
C25: 2019 | D25: 569.3 | E25: 1034.9 | F25: 21.5 | G25: 464 | H25: 845.2 | I25: 42.7 | J25: 421.5 | K25: 908.9 | L25: 32.1
C26: 2020 | D26: 458.9 | E26: 800.1 | F26: 43 | G26: 282.4 | H26: 695.8 | I26: 39.6 | J26: 271.6 | K26: 660.1 | L26: 36.5
C27: 2021 | D27: 368.5 | E27: 814.3 | F27: 40.9 | G27: 245.2 | H27: 616.9 | I27: 36.4 | J27: 244.8 | K27: 629.3 | L27: 35.1
C28: 2022 | D28: 295.2 | E28: 828.2 | F28: 20.4 | G28: 223.7 | H28: 973.6 | I28: 34.7 | J28: 210.2 | K28: 801.4 | L28: 27.6
C29: 2023 | D29: 160.8 | E29: 806.6 | F29: 15.4 | G29: 166.4 | H29: 971.9 | I29: 28.2 | J29: 138.1 | K29: 769.3 | L29: 28
C30: 2024 | D30: 94.9 | E30: 735.7 | F30: 13.4 | G30: 167.8 | H30: 933 | I30: 41.6 | J30: 122 | K30: 780 | L30: 28
C31: 2025 | D31: 86.7 | E31: 710.6 | F31: 11.9 | G31: 141.3 | H31: 981.4 | I31: 26.4 | J31: 111 | K31: 762.3 | L31: 23.1

Sheet Interesse digital
A1: Time | B1: hotel 'ro' | C1: hotel 'cf' | D1: pousada 'ro' | E1: pousada 'cf' | F1: Mês | G1: ano | H1: Demanda RO | I1: Demanda CF | K1: Mês | L1: Demanda CF / mês | M1: Demanda RO / mês
A2: 37987 | B2: 0 | C2: 27 | D2: 0 | E2: 36 | F2: =MONTH(A2) -> 1 | G2: =YEAR(A2) -> 2004 | H2: =SUM(Interesse_digital[[#This Row],[hotel ''ro'']],Interesse_digital[[#This Row],[pousada ''ro'']]) -> 0 | I2: =SUM(Interesse_digital[[#This Row],[hotel ''cf'']],Interesse_digital[[#This Row],[pousada ''cf'']]) -> 63 | K2: 1 | L2: 2617 | M2: 616
A3: 38018 | B3: 16 | C3: 22 | D3: 0 | E3: 20 | F3: =MONTH(A3) -> 2 | G3: =YEAR(A3) -> 2004 | H3: =SUM(Interesse_digital[[#This Row],[hotel ''ro'']],Interesse_digital[[#This Row],[pousada ''ro'']]) -> 16 | I3: =SUM(Interesse_digital[[#This Row],[hotel ''cf'']],Interesse_digital[[#This Row],[pousada ''cf'']]) -> 42 | K3: 2 | L3: 1447 | M3: 355
A4: 38047 | B4: 0 | C4: 0 | D4: 0 | E4: 0 | F4: =MONTH(A4) -> 3 | G4: =YEAR(A4) -> 2004 | H4: =SUM(Interesse_digital[[#This Row],[hotel ''ro'']],Interesse_digital[[#This Row],[pousada ''ro'']]) -> 0 | I4: =SUM(Interesse_digital[[#This Row],[hotel ''cf'']],Interesse_digital[[#This Row],[pousada ''cf'']]) -> 0 | K4: 3 | L4: 1109 | M4: 287
A5: 38078 | B5: 0 | C5: 21 | D5: 0 | E5: 0 | F5: =MONTH(A5) -> 4 | G5: =YEAR(A5) -> 2004 | H5: =SUM(Interesse_digital[[#This Row],[hotel ''ro'']],Interesse_digital[[#This Row],[pousada ''ro'']]) -> 0 | I5: =SUM(Interesse_digital[[#This Row],[hotel ''cf'']],Interesse_digital[[#This Row],[pousada ''cf'']]) -> 21 | K5: 4 | L5: 813 | M5: 216
A6: 38108 | B6: 0 | C6: 0 | D6: 0 | E6: 0 | F6: =MONTH(A6) -> 5 | G6: =YEAR(A6) -> 2004 | H6: =SUM(Interesse_digital[[#This Row],[hotel ''ro'']],Interesse_digital[[#This Row],[pousada ''ro'']]) -> 0 | I6: =SUM(Interesse_digital[[#This Row],[hotel ''cf'']],Interesse_digital[[#This Row],[pousada ''cf'']]) -> 0 | K6: 5 | L6: 581 | M6: 195
A7: 38139 | B7: 0 | C7: 12 | D7: 0 | E7: 16 | F7: =MONTH(A7) -> 6 | G7: =YEAR(A7) -> 2004 | H7: =SUM(Interesse_digital[[#This Row],[hotel ''ro'']],Interesse_digital[[#This Row],[pousada ''ro'']]) -> 0 | I7: =SUM(Interesse_digital[[#This Row],[hotel ''cf'']],Interesse_digital[[#This Row],[pousada ''cf'']]) -> 28 | K7: 6 | L7: 599 | M7: 200
A8: 38169 | B8: 0 | C8: 15 | D8: 0 | E8: 0 | F8: =MONTH(A8) -> 7 | G8: =YEAR(A8) -> 2004 | H8: =SUM(Interesse_digital[[#This Row],[hotel ''ro'']],Interesse_digital[[#This Row],[pousada ''ro'']]) -> 0 | I8: =SUM(Interesse_digital[[#This Row],[hotel ''cf'']],Interesse_digital[[#This Row],[pousada ''cf'']]) -> 15 | K8: 7 | L8: 896 | M8: 206
A9: 38200 | B9: 0 | C9: 0 | D9: 0 | E9: 12 | F9: =MONTH(A9) -> 8 | G9: =YEAR(A9) -> 2004 | H9: =SUM(Interesse_digital[[#This Row],[hotel ''ro'']],Interesse_digital[[#This Row],[pousada ''ro'']]) -> 0 | I9: =SUM(Interesse_digital[[#This Row],[hotel ''cf'']],Interesse_digital[[#This Row],[pousada ''cf'']]) -> 12 | K9: 8 | L9: 970 | M9: 230
A10: 38231 | B10: 0 | C10: 21 | D10: 0 | E10: 23 | F10: =MONTH(A10) -> 9 | G10: =YEAR(A10) -> 2004 | H10: =SUM(Interesse_digital[[#This Row],[hotel ''ro'']],Interesse_digital[[#This Row],[pousada ''ro'']]) -> 0 | I10: =SUM(Interesse_digital[[#This Row],[hotel ''cf'']],Interesse_digital[[#This Row],[pousada ''cf'']]) -> 44 | K10: 9 | L10: 1287 | M10: 259
A11: 38261 | B11: 0 | C11: 18 | D11: 0 | E11: 22 | F11: =MONTH(A11) -> 10 | G11: =YEAR(A11) -> 2004 | H11: =SUM(Interesse_digital[[#This Row],[hotel ''ro'']],Interesse_digital[[#This Row],[pousada ''ro'']]) -> 0 | I11: =SUM(Interesse_digital[[#This Row],[hotel ''cf'']],Interesse_digital[[#This Row],[pousada ''cf'']]) -> 40 | K11: 10 | L11: 1528 | M11: 313
A12: 38292 | B12: 0 | C12: 22 | D12: 0 | E12: 18 | F12: =MONTH(A12) -> 11 | G12: =YEAR(A12) -> 2004 | H12: =SUM(Interesse_digital[[#This Row],[hotel ''ro'']],Interesse_digital[[#This Row],[pousada ''ro'']]) -> 0 | I12: =SUM(Interesse_digital[[#This Row],[hotel ''cf'']],Interesse_digital[[#This Row],[pousada ''cf'']]) -> 40 | K12: 11 | L12: 1604 | M12: 348
A13: 38322 | B13: 0 | C13: 34 | D13: 14 | E13: 38 | F13: =MONTH(A13) -> 12 | G13: =YEAR(A13) -> 2004 | H13: =SUM(Interesse_digital[[#This Row],[hotel ''ro'']],Interesse_digital[[#This Row],[pousada ''ro'']]) -> 14 | I13: =SUM(Interesse_digital[[#This Row],[hotel ''cf'']],Interesse_digital[[#This Row],[pousada ''cf'']]) -> 72 | K13: 12 | L13: 1968 | M13: 433
A14: 38353 | B14: 9 | C14: 32 | D14: 10 | E14: 48 | F14: =MONTH(A14) -> 1 | G14: =YEAR(A14) -> 2005 | H14: =SUM(Interesse_digital[[#This Row],[hotel ''ro'']],Interesse_digital[[#This Row],[pousada ''ro'']]) -> 19 | I14: =SUM(Interesse_digital[[#This Row],[hotel ''cf'']],Interesse_digital[[#This Row],[pousada ''cf'']]) -> 80
A15: 38384 | B15: 0 | C15: 16 | D15: 0 | E15: 22 | F15: =MONTH(A15) -> 2 | G15: =YEAR(A15) -> 2005 | H15: =SUM(Interesse_digital[[#This Row],[hotel ''ro'']],Interesse_digital[[#This Row],[pousada ''ro'']]) -> 0 | I15: =SUM(Interesse_digital[[#This Row],[hotel ''cf'']],Interesse_digital[[#This Row],[pousada ''cf'']]) -> 38 | K15: ano | L15: Demanda CF / ano | M15: Demanda RO / ano
A16: 38412 | B16: 0 | C16: 20 | D16: 0 | E16: 0 | F16: =MONTH(A16) -> 3 | G16: =YEAR(A16) -> 2005 | H16: =SUM(Interesse_digital[[#This Row],[hotel ''ro'']],Interesse_digital[[#This Row],[pousada ''ro'']]) -> 0 | I16: =SUM(Interesse_digital[[#This Row],[hotel ''cf'']],Interesse_digital[[#This Row],[pousada ''cf'']]) -> 20 | K16: 2004 | L16: 377 | M16: 30
A17: 38443 | B17: 0 | C17: 0 | D17: 0 | E17: 0 | F17: =MONTH(A17) -> 4 | G17: =YEAR(A17) -> 2005 | H17: =SUM(Interesse_digital[[#This Row],[hotel ''ro'']],Interesse_digital[[#This Row],[pousada ''ro'']]) -> 0 | I17: =SUM(Interesse_digital[[#This Row],[hotel ''cf'']],Interesse_digital[[#This Row],[pousada ''cf'']]) -> 0 | K17: 2005 | L17: 396 | M17: 64
A18: 38473 | B18: 0 | C18: 0 | D18: 7 | E18: 0 | F18: =MONTH(A18) -> 5 | G18: =YEAR(A18) -> 2005 | H18: =SUM(Interesse_digital[[#This Row],[hotel ''ro'']],Interesse_digital[[#This Row],[pousada ''ro'']]) -> 7 | I18: =SUM(Interesse_digital[[#This Row],[hotel ''cf'']],Interesse_digital[[#This Row],[pousada ''cf'']]) -> 0 | K18: 2006 | L18: 541 | M18: 127
A19: 38504 | B19: 0 | C19: 0 | D19: 0 | E19: 10 | F19: =MONTH(A19) -> 6 | G19: =YEAR(A19) -> 2005 | H19: =SUM(Interesse_digital[[#This Row],[hotel ''ro'']],Interesse_digital[[#This Row],[pousada ''ro'']]) -> 0 | I19: =SUM(Interesse_digital[[#This Row],[hotel ''cf'']],Interesse_digital[[#This Row],[pousada ''cf'']]) -> 10 | K19: 2007 | L19: 603 | M19: 182
A20: 38534 | B20: 0 | C20: 14 | D20: 0 | E20: 14 | F20: =MONTH(A20) -> 7 | G20: =YEAR(A20) -> 2005 | H20: =SUM(Interesse_digital[[#This Row],[hotel ''ro'']],Interesse_digital[[#This Row],[pousada ''ro'']]) -> 0 | I20: =SUM(Interesse_digital[[#This Row],[hotel ''cf'']],Interesse_digital[[#This Row],[pousada ''cf'']]) -> 28 | K20: 2008 | L20: 676 | M20: 207
A21: 38565 | B21: 0 | C21: 12 | D21: 0 | E21: 15 | F21: =MONTH(A21) -> 8 | G21: =YEAR(A21) -> 2005 | H21: =SUM(Interesse_digital[[#This Row],[hotel ''ro'']],Interesse_digital[[#This Row],[pousada ''ro'']]) -> 0 | I21: =SUM(Interesse_digital[[#This Row],[hotel ''cf'']],Interesse_digital[[#This Row],[pousada ''cf'']]) -> 27 | K21: 2009 | L21: 941 | M21: 267
A22: 38596 | B22: 0 | C22: 10 | D22: 0 | E22: 10 | F22: =MONTH(A22) -> 9 | G22: =YEAR(A22) -> 2005 | H22: =SUM(Interesse_digital[[#This Row],[hotel ''ro'']],Interesse_digital[[#This Row],[pousada ''ro'']]) -> 0 | I22: =SUM(Interesse_digital[[#This Row],[hotel ''cf'']],Interesse_digital[[#This Row],[pousada ''cf'']]) -> 20 | K22: 2010 | L22: 851 | M22: 246
A23: 38626 | B23: 6 | C23: 21 | D23: 7 | E23: 28 | F23: =MONTH(A23) -> 10 | G23: =YEAR(A23) -> 2005 | H23: =SUM(Interesse_digital[[#This Row],[hotel ''ro'']],Interesse_digital[[#This Row],[pousada ''ro'']]) -> 13 | I23: =SUM(Interesse_digital[[#This Row],[hotel ''cf'']],Interesse_digital[[#This Row],[pousada ''cf'']]) -> 49 | K23: 2011 | L23: 793 | M23: 240
A24: 38657 | B24: 0 | C24: 29 | D24: 12 | E24: 28 | F24: =MONTH(A24) -> 11 | G24: =YEAR(A24) -> 2005 | H24: =SUM(Interesse_digital[[#This Row],[hotel ''ro'']],Interesse_digital[[#This Row],[pousada ''ro'']]) -> 12 | I24: =SUM(Interesse_digital[[#This Row],[hotel ''cf'']],Interesse_digital[[#This Row],[pousada ''cf'']]) -> 57 | K24: 2012 | L24: 768 | M24: 248
A25: 38687 | B25: 0 | C25: 29 | D25: 13 | E25: 38 | F25: =MONTH(A25) -> 12 | G25: =YEAR(A25) -> 2005 | H25: =SUM(Interesse_digital[[#This Row],[hotel ''ro'']],Interesse_digital[[#This Row],[pousada ''ro'']]) -> 13 | I25: =SUM(Interesse_digital[[#This Row],[hotel ''cf'']],Interesse_digital[[#This Row],[pousada ''cf'']]) -> 67 | K25: 2013 | L25: 747 | M25: 216
A26: 38718 | B26: 8 | C26: 43 | D26: 21 | E26: 58 | F26: =MONTH(A26) -> 1 | G26: =YEAR(A26) -> 2006 | H26: =SUM(Interesse_digital[[#This Row],[hotel ''ro'']],Interesse_digital[[#This Row],[pousada ''ro'']]) -> 29 | I26: =SUM(Interesse_digital[[#This Row],[hotel ''cf'']],Interesse_digital[[#This Row],[pousada ''cf'']]) -> 101 | K26: 2014 | L26: 843 | M26: 238
A27: 38749 | B27: 0 | C27: 16 | D27: 12 | E27: 27 | F27: =MONTH(A27) -> 2 | G27: =YEAR(A27) -> 2006 | H27: =SUM(Interesse_digital[[#This Row],[hotel ''ro'']],Interesse_digital[[#This Row],[pousada ''ro'']]) -> 12 | I27: =SUM(Interesse_digital[[#This Row],[hotel ''cf'']],Interesse_digital[[#This Row],[pousada ''cf'']]) -> 43 | K27: 2015 | L27: 887 | M27: 209
... A38: 39083 | B38: 12 | C38: 36 | D38: 19 | E38: 54 | F38: =MONTH(A38) -> 1 | G38: =YEAR(A38) -> 2007 | H38: =SUM(Interesse_digital[[#This Row],[hotel ''ro'']],Interesse_digital[[#This Row],[pousada ''ro'']]) -> 31 | I38: =SUM(Interesse_digital[[#This Row],[hotel ''cf'']],Interesse_digital[[#This Row],[pousada ''cf'']]) -> 90 | K38: 2026 | L38: 201 | M38: 48
A39: 39114 | B39: 5 | C39: 22 | D39: 10 | E39: 30 | F39: =MONTH(A39) -> 2 | G39: =YEAR(A39) -> 2007 | H39: =SUM(Interesse_digital[[#This Row],[hotel ''ro'']],Interesse_digital[[#This Row],[pousada ''ro'']]) -> 15 | I39: =SUM(Interesse_digital[[#This Row],[hotel ''cf'']],Interesse_digital[[#This Row],[pousada ''cf'']]) -> 52
A40: 39142 | B40: 4 | C40: 20 | D40: 9 | E40: 22 | F40: =MONTH(A40) -> 3 | G40: =YEAR(A40) -> 2007 | H40: =SUM(Interesse_digital[[#This Row],[hotel ''ro'']],Interesse_digital[[#This Row],[pousada ''ro'']]) -> 13 | I40: =SUM(Interesse_digital[[#This Row],[hotel ''cf'']],Interesse_digital[[#This Row],[pousada ''cf'']]) -> 42
A41: 39173 | B41: 5 | C41: 13 | D41: 6 | E41: 18 | F41: =MONTH(A41) -> 4 | G41: =YEAR(A41) -> 2007 | H41: =SUM(Interesse_digital[[#This Row],[hotel ''ro'']],Interesse_digital[[#This Row],[pousada ''ro'']]) -> 11 | I41: =SUM(Interesse_digital[[#This Row],[hotel ''cf'']],Interesse_digital[[#This Row],[pousada ''cf'']]) -> 31
A42: 39203 | B42: 3 | C42: 5 | D42: 5 | E42: 7 | F42: =MONTH(A42) -> 5 | G42: =YEAR(A42) -> 2007 | H42: =SUM(Interesse_digital[[#This Row],[hotel ''ro'']],Interesse_digital[[#This Row],[pousada ''ro'']]) -> 8 | I42: =SUM(Interesse_digital[[#This Row],[hotel ''cf'']],Interesse_digital[[#This Row],[pousada ''cf'']]) -> 12
A43: 39234 | B43: 4 | C43: 9 | D43: 6 | E43: 11 | F43: =MONTH(A43) -> 6 | G43: =YEAR(A43) -> 2007 | H43: =SUM(Interesse_digital[[#This Row],[hotel ''ro'']],Interesse_digital[[#This Row],[pousada ''ro'']]) -> 10 | I43: =SUM(Interesse_digital[[#This Row],[hotel ''cf'']],Interesse_digital[[#This Row],[pousada ''cf'']]) -> 20
A44: 39264 | B44: 3 | C44: 14 | D44: 6 | E44: 17 | F44: =MONTH(A44) -> 7 | G44: =YEAR(A44) -> 2007 | H44: =SUM(Interesse_digital[[#This Row],[hotel ''ro'']],Interesse_digital[[#This Row],[pousada ''ro'']]) -> 9 | I44: =SUM(Interesse_digital[[#This Row],[hotel ''cf'']],Interesse_digital[[#This Row],[pousada ''cf'']]) -> 31
A45: 39295 | B45: 3 | C45: 16 | D45: 7 | E45: 18 | F45: =MONTH(A45) -> 8 | G45: =YEAR(A45) -> 2007 | H45: =SUM(Interesse_digital[[#This Row],[hotel ''ro'']],Interesse_digital[[#This Row],[pousada ''ro'']]) -> 10 | I45: =SUM(Interesse_digital[[#This Row],[hotel ''cf'']],Interesse_digital[[#This Row],[pousada ''cf'']]) -> 34
A46: 39326 | B46: 4 | C46: 23 | D46: 9 | E46: 29 | F46: =MONTH(A46) -> 9 | G46: =YEAR(A46) -> 2007 | H46: =SUM(Interesse_digital[[#This Row],[hotel ''ro'']],Interesse_digital[[#This Row],[pousada ''ro'']]) -> 13 | I46: =SUM(Interesse_digital[[#This Row],[hotel ''cf'']],Interesse_digital[[#This Row],[pousada ''cf'']]) -> 52
A47: 39356 | B47: 6 | C47: 29 | D47: 12 | E47: 38 | F47: =MONTH(A47) -> 10 | G47: =YEAR(A47) -> 2007 | H47: =SUM(Interesse_digital[[#This Row],[hotel ''ro'']],Interesse_digital[[#This Row],[pousada ''ro'']]) -> 18 | I47: =SUM(Interesse_digital[[#This Row],[hotel ''cf'']],Interesse_digital[[#This Row],[pousada ''cf'']]) -> 67
A48: 39387 | B48: 8 | C48: 30 | D48: 11 | E48: 35 | F48: =MONTH(A48) -> 11 | G48: =YEAR(A48) -> 2007 | H48: =SUM(Interesse_digital[[#This Row],[hotel ''ro'']],Interesse_digital[[#This Row],[pousada ''ro'']]) -> 19 | I48: =SUM(Interesse_digital[[#This Row],[hotel ''cf'']],Interesse_digital[[#This Row],[pousada ''cf'']]) -> 65
A49: 39417 | B49: 9 | C49: 48 | D49: 16 | E49: 59 | F49: =MONTH(A49) -> 12 | G49: =YEAR(A49) -> 2007 | H49: =SUM(Interesse_digital[[#This Row],[hotel ''ro'']],Interesse_digital[[#This Row],[pousada ''ro'']]) -> 25 | I49: =SUM(Interesse_digital[[#This Row],[hotel ''cf'']],Interesse_digital[[#This Row],[pousada ''cf'']]) -> 107
A50: 39448 | B50: 11 | C50: 49 | D50: 26 | E50: 70 | F50: =MONTH(A50) -> 1 | G50: =YEAR(A50) -> 2008 | H50: =SUM(Interesse_digital[[#This Row],[hotel ''ro'']],Interesse_digital[[#This Row],[pousada ''ro'']]) -> 37 | I50: =SUM(Interesse_digital[[#This Row],[hotel ''cf'']],Interesse_digital[[#This Row],[pousada ''cf'']]) -> 119
...

Sheet Empregos Turismo
B2: EMPREGOS FORMAIS NO TURISMO / 1k habitantes | F2: VARIAÇÃO % ANUAL — Empregos no Turismo
B3: Ano | C3: Rio das Ostras | D3: Cabo Frio | F3: Ano | G3: Rio das Ostras | H3: Cabo Frio
B4: 2010 | C4: 4.8828495 | D4: 6.5565144 | F4: 2010 | G4: - | H4: -
B5: 2011 | C5: 4.378694 | D5: 7.5852489 | F5: 2011 | G5: -5.8 | H5: 18.5
B6: 2012 | C6: 4.3914788 | D6: 7.7520968 | F6: 2012 | G6: 4.9 | H6: 4.6
B7: 2013 | C7: 5.6384824 | D7: 8.3116493 | F7: 2013 | G7: 35.1 | H7: 9.7
B8: 2014 | C8: 4.8202814 | D8: 8.4255644 | F8: 2014 | G8: -11 | H8: 3.7
B9: 2015 | C9: 4.3568528 | D9: 8.8983558 | F9: 2015 | G9: -6.2 | H9: 8
B10: 2016 | C10: 2.8252309 | D10: 9.4025383 | F10: 2016 | G10: -32.9 | H10: 8
B11: 2017 | C11: 2.3739167 | D11: 8.9361897 | F11: 2017 | G11: -13.2 | H11: -2.9
B12: 2018 | C12: 2.1302975 | D12: 8.3315358 | F12: 2018 | G12: -7.2 | H12: -4.8
B13: 2019 | C13: 2.143701 | D13: 8.110198 | F13: 2019 | G13: 3.9 | H13: -2.7
B14: 2020 | C14: 1.9975128 | D14: 8.1000612 | F14: 2020 | G14: -4 | H14: -0.2
B15: 2021 | C15: 2.1751531 | D15: 7.9009057 | F15: 2021 | G15: 11.9 | H15: -2.5

Sheet Total Empregos Formais
B1: TOTAL EMPREGOS FORMAIS / mil habitantes | F1: % EMPREGOS NO TURISMO / TOTAL FORMAL | J1: VARIAÇÃO % ANUAL — Total Empregos Formais
B2: Ano | C2: Rio das Ostras | D2: Cabo Frio | F2: Ano | G2: Rio das Ostras | H2: Cabo Frio | J2: Ano | K2: Rio das Ostras | L2: Cabo Frio
B3: 2010 | C3: 283.26205 | D3: 304.40806 | F3: 2010 | G3: =('Empregos Turismo'!C4)/(Tabela27[[#This Row],[Rio das Ostras]]) -> 0.017237923 | H3: =('Empregos Turismo'!D4)/(Tabela27[[#This Row],[Cabo Frio]]) -> 0.02153857 | J3: 2010 | K3: - | L3: -
B4: 2011 | C4: 292.65172 | D4: 327.04637 | F4: 2011 | G4: =('Empregos Turismo'!C5)/(Tabela27[[#This Row],[Rio das Ostras]]) -> 0.014962133 | H4: =('Empregos Turismo'!D5)/(Tabela27[[#This Row],[Cabo Frio]]) -> 0.023193191 | J4: 2011 | K4: 8.5 | L4: 10.1
B5: 2012 | C5: 328.68066 | D5: 336.37136 | F5: 2012 | G5: =('Empregos Turismo'!C6)/(Tabela27[[#This Row],[Rio das Ostras]]) -> 0.013360928 | H5: =('Empregos Turismo'!D6)/(Tabela27[[#This Row],[Cabo Frio]]) -> 0.023046245 | J5: 2012 | K5: 17.5 | L5: 5.3
B6: 2013 | C6: 534.78837 | D6: 368.34968 | F6: 2013 | G6: =('Empregos Turismo'!C7)/(Tabela27[[#This Row],[Rio das Ostras]]) -> 0.01054339 | H6: =('Empregos Turismo'!D7)/(Tabela27[[#This Row],[Cabo Frio]]) -> 0.022564562 | J6: 2013 | K6: 71.2 | L6: 12.1
B7: 2014 | C7: 372.08955 | D7: 366.79095 | F7: 2014 | G7: =('Empregos Turismo'!C8)/(Tabela27[[#This Row],[Rio das Ostras]]) -> 0.012954627 | H7: =('Empregos Turismo'!D8)/(Tabela27[[#This Row],[Cabo Frio]]) -> 0.022971026 | J7: 2014 | K7: -27.6 | L7: 1.8
B8: 2015 | C8: 356.28448 | D8: 354.24455 | F8: 2015 | G8: =('Empregos Turismo'!C9)/(Tabela27[[#This Row],[Rio das Ostras]]) -> 0.012228579 | H8: =('Empregos Turismo'!D9)/(Tabela27[[#This Row],[Cabo Frio]]) -> 0.025119245 | J8: 2015 | K8: -0.6 | L8: -1.3
B9: 2016 | C9: 287.96862 | D9: 318.2621 | F9: 2016 | G9: =('Empregos Turismo'!C10)/(Tabela27[[#This Row],[Rio das Ostras]]) -> 0.0098108987 | H9: =('Empregos Turismo'!D10)/(Tabela27[[#This Row],[Cabo Frio]]) -> 0.02954338 | J9: 2016 | K9: -16.3 | L9: -8.2
B10: 2017 | C10: 267.99748 | D10: 296.66498 | F10: 2017 | G10: =('Empregos Turismo'!C11)/(Tabela27[[#This Row],[Rio das Ostras]]) -> 0.0088579814 | H10: =('Empregos Turismo'!D11)/(Tabela27[[#This Row],[Cabo Frio]]) -> 0.030122159 | J10: 2017 | K10: -3.9 | L10: -4.8
B11: 2018 | C11: 256.33438 | D11: 298.42537 | F11: 2018 | G11: =('Empregos Turismo'!C12)/(Tabela27[[#This Row],[Rio das Ostras]]) -> 0.0083106194 | H11: =('Empregos Turismo'!D12)/(Tabela27[[#This Row],[Cabo Frio]]) -> 0.027918323 | J11: 2018 | K11: -1 | L11: 2.7
B12: 2019 | C12: 259.91213 | D12: 302.11387 | F12: 2019 | G12: =('Empregos Turismo'!C13)/(Tabela27[[#This Row],[Rio das Ostras]]) -> 0.0082477912 | H12: =('Empregos Turismo'!D13)/(Tabela27[[#This Row],[Cabo Frio]]) -> 0.026844839 | J12: 2019 | K12: 4.6 | L12: 1.2
B13: 2020 | C13: 250.64919 | D13: 274.59702 | F13: 2020 | G13: =('Empregos Turismo'!C14)/(Tabela27[[#This Row],[Rio das Ostras]]) -> 0.0079693565 | H13: =('Empregos Turismo'!D14)/(Tabela27[[#This Row],[Cabo Frio]]) -> 0.029497994 | J13: 2020 | K13: -0.7 | L13: -9.1
B14: 2021 | C14: 261.81447 | D14: 294.5922 | F14: 2021 | G14: =('Empregos Turismo'!C15)/(Tabela27[[#This Row],[Rio das Ostras]]) -> 0.0083079943 | H14: =('Empregos Turismo'!D15)/(Tabela27[[#This Row],[Cabo Frio]]) -> 0.026819806 | J14: 2021 | K14: 7.4 | L14: 7.2

Sheet PIB per Capita
B1: PIB PER CAPITA (R$ correntes)
B2: Ano | C2: Rio das Ostras | D2: Cabo Frio | E2: Macaé
B3: 2010 | C3: =C20/População!C9 -> 84767.374 | D3: =(D20/População!D9) -> 49944.847 | E3: =(E20/População!E9) -> 65851.617
B4: 2011 | C4: =C21/População!C10 -> 112768.31 | D4: =(D21/População!D10) -> 66116.536 | E4: =(E21/População!E10) -> 68596.715
B5: 2012 | C5: =C22/População!C11 -> 128449.98 | D5: =(D22/População!D11) -> 85839.659 | E5: =(E22/População!E11) -> 78759.335
B6: 2013 | C6: =C23/População!C12 -> 121883.19 | D6: =(D23/População!D12) -> 84397.768 | E6: =(E23/População!E12) -> 85131.755
B7: 2014 | C7: =C24/População!C13 -> 112731.35 | D7: =(D24/População!D13) -> 84197.609 | E7: =(E24/População!E13) -> 93460.031
B8: 2015 | C8: =C25/População!C14 -> 66045.501 | D8: =(D25/População!D14) -> 50925.726 | E8: =(E25/População!E14) -> 83782.961
B9: 2016 | C9: =C26/População!C15 -> 35783.123 | D9: =(D26/População!D15) -> 33765.466 | E9: =(E26/População!E15) -> 73089.778
B10: 2017 | C10: =C27/População!C16 -> 39701.73 | D10: =(D27/População!D16) -> 39454.195 | E10: =(E27/População!E16) -> 62509.329
B11: 2018 | C11: =C28/População!C17 -> 58849.256 | D11: =(D28/População!D17) -> 49307.094 | E11: =(E28/População!E17) -> 61340.463
B12: 2019 | C12: =C29/População!C18 -> 51404.522 | D12: =(D29/População!D18) -> 51795.654 | E12: =(E29/População!E18) -> 58887.724
B13: 2020 | C13: =C30/População!C19 -> 40869.195 | D13: =(D30/População!D19) -> 41953.842 | E13: =(E30/População!E19) -> 58773.969
B14: 2021 | C14: =C31/População!C20 -> 56096.359 | D14: =(D31/População!D20) -> 55610.089 | E14: =(E31/População!E20) -> 66683.151
... B16: 2023 | C16: =C33/População!C22 -> 65312.536 | D16: =(D33/População!D22) -> 73706.018 | E16: =(E33/População!E22) -> 88725.194
B18: PIB
B19: Ano | C19: Rio das Ostras | D19: Cabo Frio | E19: Macaé
B20: 2010 | C20: 8957877000 | D20: 9301079000 | E20: 13613373000
B21: 2011 | C21: 12516380000 | D21: 12612721000 | E21: 14565895000
B22: 2012 | C22: 14917410000 | D22: 16764657000 | E22: 17165912000
B23: 2013 | C23: 14893638000 | D23: 16866050000 | E23: 19032651000
B24: 2014 | C24: 14336159000 | D24: 17208139000 | E24: 21419170000
B25: 2015 | C25: 8716421000 | D25: 10639148000 | E25: 19671569000
B26: 2016 | C26: 4888905000 | D26: 7207340000 | E26: 17571148000
B27: 2017 | C27: 5602589000 | D27: 8600620000 | E27: 15378420000
B28: 2018 | C28: 8591344000 | D28: 10972209000 | E28: 15435162000
B29: 2019 | C29: 7745325000 | D29: 11521218000 | E29: 15102699000
B30: 2020 | C30: 6342613000 | D30: 9328185000 | E30: 15357697000
B31: 2021 | C31: 8948996000 | D31: 12359509000 | E31: 17746787000
... B33: 2023 | C33: 10599898000 | D33: 16964472000 | E33: 22394860000

Sheet Receitas_Despesas
B2: RECEITAS ORÇAMENTÁRIAS BRUTAS | G2: DESPESAS ORÇAMENTÁRIAS BRUTAS | L2: RECEITAS / HABITANTE | Q2: DESPESAS / HABITANTE | V2: SALDO LÍQUIDO
B3: Ano | C3: Cabo Frio | D3: Macaé | E3: Rio das Ostras | G3: Ano | H3: Cabo Frio | I3: Macaé | J3: Rio das Ostras | L3: Ano | M3: Cabo Frio | N3: Macaé | O3: Rio das Ostras | Q3: Ano | R3: Cabo Frio | S3: Macaé | T3: Rio das Ostras | V3: Ano | W3: Cabo Frio | X3: Macaé | Y3: Rio das Ostras
B4: 2013 | C4: 8.5924828e+08 | D4: 2.1673717e+09 | E4: 7.187155e+08 | G4: 2013 | H4: 7.5575731e+08 | I4: 1709598814 | J4: 6.2727826e+08 | L4: 2013 | M4: =C4/População!D12 -> 4299.6811 | N4: =D4/População!E12 -> 9694.5063 | O4: =E4/População!C12 -> 5881.6614 | Q4: 2013 | R4: =H4/População!D12 -> 3781.812 | S4: =I4/População!E12 -> 7646.9193 | T4: =J4/População!C12 -> 5133.378 | V4: 2013 | W4: =Tabela15[[#This Row],[Cabo Frio]]-Tabela19[[#This Row],[Cabo Frio]] -> 1.0349097e+08 | X4: =D4-I4 -> 4.5777289e+08 | Y4: =E4-J4 -> 91437244
B5: 2014 | C5: 9.2970877e+08 | D5: =AVERAGE(D4,D6) -> 2.1958688e+09 | E5: 7.6508494e+08 | G5: 2014 | H5: 8.9424665e+08 | I5: =AVERAGE(I4,I6) -> 1.8453916e+09 | J5: 7.0170156e+08 | L5: 2014 | M5: =C5/População!D13 -> 4548.967 | N5: =D5/População!E13 -> 9581.4153 | O5: =E5/População!C13 -> 6016.1903 | Q5: 2014 | R5: =H5/População!D13 -> 4375.4545 | S5: =I5/População!E13 -> 8052.1493 | T5: =J5/População!C13 -> 5517.7797 | V5: 2014 | W5: =Tabela15[[#This Row],[Cabo Frio]]-Tabela19[[#This Row],[Cabo Frio]] -> 35462123 | X5: =D5-I5 -> 3.5047717e+08 | Y5: =E5-J5 -> 63383374
B6: 2015 | C6: 7.6116401e+08 | D6: 2.2243658e+09 | E6: 6.2259869e+08 | G6: 2015 | H6: 6.6337079e+08 | I6: 1981184349 | J6: 5.2442515e+08 | L6: 2015 | M6: =C6/População!D14 -> 3643.4148 | N6: =D6/População!E14 -> 9473.7717 | O6: =E6/População!C14 -> 4717.5145 | Q6: 2015 | R6: =H6/População!D14 -> 3175.3143 | S6: =I6/População!E14 -> 8438.0403 | T6: =J6/População!C14 -> 3973.6403 | V6: 2015 | W6: =Tabela15[[#This Row],[Cabo Frio]]-Tabela19[[#This Row],[Cabo Frio]] -> 97793220 | X6: =D6-I6 -> 2.4318146e+08 | Y6: =E6-J6 -> 98173541
B7: 2016 | C7: 6.2704848e+08 | D7: 2.0747577e+09 | E7: 5.5445939e+08 | G7: 2016 | H7: 3.1990648e+08 | I7: 1766857059 | J7: 4.6176737e+08 | L7: 2016 | M7: =C7/População!D15 -> 2937.6419 | N7: =D7/População!E15 -> 8630.2601 | O7: =E7/População!C15 -> 4058.2275 | Q7: 2016 | R7: =H7/População!D15 -> 1498.721 | S7: =I7/População!E15 -> 7349.5021 | T7: =J7/População!C15 -> 3379.7914 | V7: 2016 | W7: =Tabela15[[#This Row],[Cabo Frio]]-Tabela19[[#This Row],[Cabo Frio]] -> 3.07142e+08 | X7: =D7-I7 -> 3.0790062e+08 | Y7: =E7-J7 -> 92692015
B8: 2017 | C8: 8.0297809e+08 | D8: 1.9781943e+09 | E8: 5.7412589e+08 | G8: 2017 | H8: 6.7207496e+08 | I8: 1798305022 | J8: 407060811 | L8: 2017 | M8: =C8/População!D16 -> 3683.5547 | N8: =D8/População!E16 -> 8040.8518 | O8: =E8/População!C16 -> 4068.4389 | Q8: 2017 | R8: =H8/População!D16 -> 3083.0541 | S8: =I8/População!E16 -> 7309.6482 | T8: =J8/População!C16 -> 2884.5625 | V8: 2017 | W8: =Tabela15[[#This Row],[Cabo Frio]]-Tabela19[[#This Row],[Cabo Frio]] -> 1.3090313e+08 | X8: =D8-I8 -> 1.7988925e+08 | Y8: =E8-J8 -> 1.6706508e+08
B9: 2018 | C9: 9.0568944e+08 | D9: 2.5768303e+09 | E9: 6.8247046e+08 | G9: 2018 | H9: 7.3722398e+08 | I9: 1837394693 | J9: 529408646 | L9: 2018 | M9: =C9/População!D17 -> 4070.0021 | N9: =D9/População!E17 -> 10240.512 | O9: =E9/População!C17 -> 4674.8074 | Q9: 2018 | R9: =H9/População!D17 -> 3312.9493 | S9: =I9/População!E17 -> 7301.9409 | T9: =J9/População!C17 -> 3626.3598 | V9: 2018 | W9: =Tabela15[[#This Row],[Cabo Frio]]-Tabela19[[#This Row],[Cabo Frio]] -> 1.6846546e+08 | X9: =D9-I9 -> 7.3943561e+08 | Y9: =E9-J9 -> 1.5306182e+08
B10: 2019 | C10: 9.0914462e+08 | D10: 2.2279267e+09 | E10: 6.6944342e+08 | G10: 2019 | H10: 8.0000415e+08 | I10: 2029560307 | J10: 5.7984112e+08 | L10: 2019 | M10: =C10/População!D18 -> 4087.2189 | N10: =D10/População!E18 -> 8687.0257 | O10: =E10/População!C18 -> 4442.9923 | Q10: 2019 | R10: =H10/População!D18 -> 3596.5588 | S10: =I10/População!E18 -> 7913.5648 | T10: =J10/População!C18 -> 3848.3157 | V10: 2019 | W10: =Tabela15[[#This Row],[Cabo Frio]]-Tabela19[[#This Row],[Cabo Frio]] -> 1.0914047e+08 | X10: =D10-I10 -> 1.9836641e+08 | Y10: =E10-J10 -> 89602294
B11: 2020 | C11: 9.0996228e+08 | D11: 2521222323 | E11: 6.6301979e+08 | G11: 2020 | H11: 817289082 | I11: 2100571932 | J11: 5.908087e+08 | L11: 2020 | M11: =C11/População!D19 -> 4092.5875 | N11: =D11/População!E19 -> 9648.7282 | O11: =E11/População!C19 -> 4272.2274 | Q11: 2020 | R11: =H11/População!D19 -> 3675.7865 | S11: =I11/População!E19 -> 8038.8974 | T11: =J11/População!C19 -> 3806.9288 | V11: 2020 | W11: =Tabela15[[#This Row],[Cabo Frio]]-Tabela19[[#This Row],[Cabo Frio]] -> 92673196 | X11: =D11-I11 -> 420650391 | Y11: =E11-J11 -> 72211086
B12: 2021 | C12: 1.1924636e+09 | D12: 3.0863216e+09 | E12: 8.6619063e+08 | G12: 2021 | H12: 1009223617 | I12: 2079048258 | J12: 6.4542834e+08 | L12: 2021 | M12: =C12/População!D20 -> 5365.343 | N12: =D12/População!E20 -> 11596.784 | O12: =E12/População!C20 -> 5429.675 | Q12: 2021 | R12: =H12/População!D20 -> 4540.8774 | S12: =I12/População!E20 -> 7811.9768 | T12: =J12/População!C20 -> 4045.837 | V12: 2021 | W12: =Tabela15[[#This Row],[Cabo Frio]]-Tabela19[[#This Row],[Cabo Frio]] -> 1.8323996e+08 | X12: =D12-I12 -> 1.0072734e+09 | Y12: =E12-J12 -> 2.2076229e+08
B13: 2022 | C13: 1.3194667e+09 | D13: 3.9492683e+09 | E13: 1.095413e+09 | G13: 2022 | H13: 1.2905537e+09 | I13: 2.5350436e+09 | J13: 8.4122485e+08 | L13: 2022 | M13: =C13/População!D21 -> 5939.2363 | N13: =D13/População!E21 -> 16028.46 | O13: =E13/População!C21 -> 6999.8465 | Q13: 2022 | R13: =H13/População!D21 -> 5809.0922 | S13: =I13/População!E21 -> 10288.702 | T13: =J13/População!C21 -> 5375.5478 | V13: 2022 | W13: =Tabela15[[#This Row],[Cabo Frio]]-Tabela19[[#This Row],[Cabo Frio]] -> 28912936 | X13: =D13-I13 -> 1.4142246e+09 | Y13: =E13-J13 -> 2.5418813e+08
B14: 2023 | C14: 1.5113189e+09 | D14: 4.2451944e+09 | E14: 1.1145267e+09 | G14: 2023 | H14: 1.3986245e+09 | I14: 3.0190085e+09 | J14: 1.0206332e+09 | L14: 2023 | M14: =C14/População!D22 -> 6566.2699 | N14: =D14/População!E22 -> 16818.846 | O14: =E14/População!C22 -> 6867.2893 | Q14: 2023 | R14: =H14/População!D22 -> 6076.6433 | S14: =I14/População!E22 -> 11960.875 | T14: =J14/População!C22 -> 6288.7535 | V14: 2023 | W14: =Tabela15[[#This Row],[Cabo Frio]]-Tabela19[[#This Row],[Cabo Frio]] -> 1.1269441e+08 | X14: =D14-I14 -> 1.2261859e+09 | Y14: =E14-J14 -> 93893481
B15: 2024 | C15: 1.5297659e+09 | D15: 4.7076748e+09 | E15: 1.1424886e+09 | G15: 2024 | H15: 1.5819679e+09 | I15: 3.5805914e+09 | J15: 1.0663142e+09 | L15: 2024 | M15: =C15/População!D23 -> 6423.1078 | N15: =D15/População!E23 -> 18216.934 | O15: =E15/População!C23 -> 6796.5221 | Q15: 2024 | R15: =H15/População!D23 -> 6642.2911 | S15: =I15/População!E23 -> 13855.545 | T15: =J15/População!C23 -> 6343.3702 | V15: 2024 | W15: =Tabela15[[#This Row],[Cabo Frio]]-Tabela19[[#This Row],[Cabo Frio]] -> -52202002 | X15: =D15-I15 -> 1.1270835e+09 | Y15: =E15-J15 -> 76174385

Sheet IDHM
A1: IDHM E SUBÍNDICES
A3: Dimensão | B3: Cidade | C3: 2000 | D3: 2010 | E3: 2021 | F3: Δ 2000→2010 | G3: Δ 2010→2021
A4: IDHM Geral | B4: Rio das Ostras | C4: 0.659 | D4: 0.773 | E4: 0.797 | F4: 17.3 | G4: 3.1
B5: Cabo Frio | C5: 0.729 | D5: 0.759 | E5: 0.773 | F5: 4.1 | G5: 1.8
B6: Macaé | C6: 0.736 | D6: 0.764 | E6: 0.778 | F6: 3.8 | G6: 1.8
A8: Longevidade | B8: Rio das Ostras | C8: 0.762 | D8: 0.854 | E8: 0.873 | F8: 12.1 | G8: 2.2
B9: Cabo Frio | C9: 0.801 | D9: 0.845 | E9: 0.861 | F9: 5.5 | G9: 1.9
B10: Macaé | C10: 0.789 | D10: 0.851 | E10: 0.867 | F10: 7.9 | G10: 1.9
A12: Renda | B12: Rio das Ostras | C12: 0.709 | D12: 0.784 | E12: 0.79 | F12: 10.6 | G12: 0.8
B13: Cabo Frio | C13: 0.742 | D13: 0.762 | E13: 0.771 | F13: 2.7 | G13: 1.2
B14: Macaé | C14: 0.751 | D14: 0.775 | E14: 0.779 | F14: 3.2 | G14: 0.5
A16: Educação | B16: Rio das Ostras | C16: 0.53 | D16: 0.686 | E16: 0.733 | F16: 29.4 | G16: 6.9
B17: Cabo Frio | C17: 0.65 | D17: 0.678 | E17: 0.691 | F17: 4.3 | G17: 1.9
B18: Macaé | C18: 0.672 | D18: 0.673 | E18: 0.693 | F18: 0.1 | G18: 3

Sheet ANALYZE
A1: Indicador | B1: Pergunta | C1: Resposta | D1: Hipótese
A2: População | B2: Crescimento acima da média regional? | C2: Não, o crescimento populacional seguiu proporcional à média regional. | D2: -
A3: Homicídio doloso | B3: O crescimento foi contínuo? | C3: Não, os índices de homicídio doloso estiveram a maior parte do tempo inferior à média regional, tendo apenas um pico entre 2019 e 2021. Desde então continuou em queda. | D3: Possivelmente reflexo do investimento municipal em segurança, além da distribuição da polícia militar pelo governo do estado do Rio de Janeiro na Região dos Lagos. (limitações: não foi possível levantar os dados de investimento na segurança pública)
A4: Furtos e Roubos | B4: O crescimento foi contínuo? | C4: Não, tanto furtos quanto roubos por 100k habitantes mantiveram-se consistentemente acima da média da Região dos Lagos entre 2014 e 2023, ainda que em tendência de queda constante. Em 2024, pela primeira vez, ambos os indicadores ficaram abaixo da média regional. | D4: Furtos apresentam correlação muito forte com empregos no setor de turismo (Pearson = 0,93), sugerindo que a queda nos furtos acompanha diretamente a redução do fluxo turístico na cidade. Já roubos não apresentam correlação relevante com turismo (Pearson = 0,13), indicando que sua trajetória de queda responde a outros fatores não capturados neste projeto. Isso sugere que estratégias para aumentar o turismo devem antecipar um possível aumento em furtos
A5: Empregos no setor de turismo | B5: O crescimento foi abaixo da média de Cabo Frio? | C5: Os empregos formais no setor do turismo estavam em torno de 5 por mil habitantes em 2010, caindo para 2 em 2021, enquanto Cabo Frio foi de 7 para 8 empregos. | D5: Baixo investimento municipal nos pontos turísticos e na divulgação da cidade nas redes sociais.
A6: IDH | B6: O crescimento foi contínuo? | C6: SIm, ultrapassando em 2008 os índices de Cabo Frio e Macaé. | D6: Influenciado por ter um aumento de 35% no índice de educação entre 2000 e 2021, muito superior aos outros dois municípios, entretanto se mantém sendo o indicador de menor valor.
A7: Arrecadação | B7: O crescimento foi proporcional à população? | C7: A receita se manteve proporcional por habitante, assim como Cabo Frio. Entretanto, Macaé teve um aumento considerável de 8 mil para 18 mil / habitante entre 2017 e 2024. | D7: A menor presença de atividades econômicas de alta geração de valor agregado e arrecadação tributária limita o crescimento da receita municipal por habitante em Rio das Ostras.
A8: PIB per capita | B8: Crescimento foi lento? | C8: De 2012 a 2016 teve uma queda de 128 mil para 35 mil, tendo um crescimento de 50% entre 2020 e 2023, mantendo na casa dos 65 mil. | D8: Alta dependência do setor petrolífero, que teve sua crise em 2014.
F20: RIO DAS OSTRAS | J20: RIO DAS OSTRAS | N20: RIO DAS OSTRAS | R20: RIO DAS OSTRAS
F21: Ano | G21: PIB per capita | H21: Empregos formais no turismo | J21: Ano | K21: PIB per capita | L21: Empregos formais totais | N21: Ano | O21: interesse digital | P21: Empregos formais no turismo | R21: Ano | S21: Roubos | T21: Furtos | U21: Empregos no Setor do Turismo
F22: 2010 | G22: 84767.374 | H22: 516 | J22: 2010 | K22: 84767.374 | L22: =('Total Empregos Formais'!C3)*(População!C9)/1000 -> 29934 | N22: 2010 | O22: 246 | P22: 516 | R22: 2014 | S22: 681.1 | T22: 1439.2 | U22: 613
F23: 2011 | G23: 112768.31 | H23: 486 | J23: 2011 | K23: 112768.31 | L23: =('Total Empregos Formais'!C4)*(População!C10)/1000 -> 32482 | N23: 2011 | O23: 240 | P23: 486 | R23: 2015 | S23: 565.4 | T23: 1373.9 | U23: 575
F24: 2012 | G24: 128449.98 | H24: 510 | J24: 2012 | K24: 128449.98 | L24: =('Total Empregos Formais'!C5)*(População!C11)/1000 -> 38171 | N24: 2012 | O24: 248 | P24: 510 | R24: 2016 | S24: 804.9 | T24: 1129.4 | U24: 386
F25: 2013 | G25: 121883.19 | H25: 689 | J25: 2013 | K25: 121883.19 | L25: =('Total Empregos Formais'!C6)*(População!C12)/1000 -> 65349 | N25: 2013 | O25: 216 | P25: 689 | R25: 2017 | S25: 651.3 | T25: 946.4 | U25: 335
F26: 2014 | G26: 112731.35 | H26: 613 | J26: 2014 | K26: 112731.35 | L26: =('Total Empregos Formais'!C7)*(População!C13)/1000 -> 47319 | N26: 2014 | O26: 238 | P26: 613 | R26: 2018 | S26: 779.5 | T26: 886.4 | U26: 311
F27: 2015 | G27: 66045.501 | H27: 575 | J27: 2015 | K27: 66045.501 | L27: =('Total Empregos Formais'!C8)*(População!C14)/1000 -> 47021 | N27: 2015 | O27: 209 | P27: 575 | R27: 2019 | S27: 569.3 | T27: 1034.9 | U27: 323
F28: 2016 | G28: 35783.123 | H28: 386 | J28: 2016 | K28: 35783.123 | L28: =('Total Empregos Formais'!C9)*(População!C15)/1000 -> 39344 | N28: 2016 | O28: 148 | P28: 386 | R28: 2020 | S28: 458.9 | T28: 800.1 | U28: 310
F29: 2017 | G29: 39701.73 | H29: 335 | J29: 2017 | K29: 39701.73 | L29: =('Total Empregos Formais'!C10)*(População!C16)/1000 -> 37819 | N29: 2017 | O29: 130 | P29: 335 | R29: 2021 | S29: 368.5 | T29: 814.3 | U29: 347
F30: 2018 | G30: 58849.256 | H30: 311 | J30: 2018 | K30: 58849.256 | L30: =('Total Empregos Formais'!C11)*(População!C17)/1000 -> 37422 | N30: 2018 | O30: 148 | P30: 311
F31: 2019 | G31: 51404.522 | H31: 323 | J31: 2019 | K31: 51404.522 | L31: =('Total Empregos Formais'!C12)*(População!C18)/1000 -> 39162 | N31: 2019 | O31: 149 | P31: 323 | R31: Pearson de Roubos x Empregos no Turismo = 0,1269 | U31: correlação positiva fraca
F32: 2020 | G32: 40869.195 | H32: 310 | J32: 2020 | K32: 40869.195 | L32: =('Total Empregos Formais'!C13)*(População!C19)/1000 -> 38899 | N32: 2020 | O32: 126 | P32: 310
F33: 2021 | G33: 56096.359 | H33: 347 | J33: 2021 | K33: 56096.359 | L33: =('Total Empregos Formais'!C14)*(População!C20)/1000 -> 41767 | N33: 2021 | O33: 129 | P33: 347 | R33: Pearson de Furtos x Empregos no Turismo = 0,9339 | U33: correlação positiva muito forte
F35: Pearson = | G35: 0.7952 | H35: correlação positiva forte | J35: Pearson = | K35: 0.312 | L35: correlação positiva fraca | N35: Pearson = | O35: 0.8258 | P35: correlação positiva forte | R35: A correlação muito forte entre furtos e empregos no turismo sugere que furto é, em grande parte, um crime associado à presença de turistas, quando a atividade turística cai, os furtos caem na mesma proporção. Esse achado pode ter implicação direta para o Improve: qualquer estratégia de retomada do turismo deve prever reforço de segurança preventiva em áreas turísticas, já que o aumento de visitantes provavelmente trará de volta parte dos furtos
F37: Existe forte associação entre o PIB per capita de RO e o volume de empregos formais no setor de turismo — as duas séries sobem e caem de forma sincronizada ao longo de 2010-2021. Isso sugere que o turismo, embora represente uma fração pequena do total de empregos da cidade (menos de 2%), tem peso desproporcional na explicação da variação da renda per capita. Investir em turismo pode ter efeito multiplicador maior que investir em emprego genérico. | J37: Em contraste com o resultado anterior, o total de empregos formais (todos os setores) tem correlação fraca com o PIB per capita. Isso reforça que a renda per capita de RO não é explicada pelo volume geral de emprego, mas por setores específicos de maior valor agregado — o que aponta para o turismo (e historicamente o petróleo) como os verdadeiros motores da renda, não o mercado de trabalho como um todo. | N37: A demanda digital por hospedagem (Google Trends) acompanha de perto o volume de empregos formais no setor, ambos caem de forma consistente a partir de 2014. Isso sugere que a visibilidade digital da cidade como destino turístico é um indicador da saúde do setor de hospedagem, ou uma consequência junto com este. De qualquer maneira, reforça a recomendação de ter o marketing digital como alavanca de recuperação no Improve.
R47: Diferente de furtos, roubos não acompanham a atividade turística, a correlação é praticamente nula. Isso indica que a queda de roubos em RO responde a fatores estruturais não relacionados ao turismo, possivelmente ligados à dinâmica de criminalidade urbana local. Para o Improve, isso significa que a estratégia de segurança não pode ser unidimensional: combater roubos exige abordagem distinta de prevenir furtos turísticos.

Sheet IMPROVE
A1: IMPROVE — Plano de Ação (PDSA)
A2: As ações abaixo derivam diretamente das causas mapeadas no Diagrama de Ishikawa (Analyze) e das correlações estatísticas identificadas. Cada ação está vinculada à categoria de causa, ao indicador que deve impactar, e segue o ciclo PDSA (Plan-Do-Study-Act) para permitir avaliação futura no Control.
A4: MATRIZ DE PRIORIZAÇÃO DE AÇÕES
A5: Categoria (Ishikawa) | B5: Causa Raiz Endereçada | C5: Ação Proposta | D5: Indicador-Alvo | E5: Evidência (Analyze) | F5: Impacto | G5: Esforço | H5: Prioridade
A6: Gestão e Planejamento | B6: Ausência de estratégia municipal de turismo | C6: Criar Plano Municipal de Turismo com metas anuais de ocupação hoteleira, empregos no setor e arrecadação de ISS turístico | D6: Empregos no Turismo / 1k hab | E6: RO caiu de 4,88 para 2,18 (2010-2021); CF subiu de 6,56 para 7,90 | F6: Alto | G6: Médio | H6: P1
A7: Gestão e Planejamento | B7: Sem incentivo fiscal para hospedagem/lazer | C7: Programa de incentivo fiscal (ISS reduzido por 24 meses) para novos empreendimentos de hospedagem e lazer | D7: Empregos no Turismo / 1k hab | E7: % empregos turismo/total caiu de 1,7% para 0,8% em RO; subiu de 2,2% para 3,0% em CF | F7: Alto | G7: Médio | H7: P1
A8: Gestão e Planejamento | B8: Falta de plano de marketing digital | C8: Estratégia de marketing digital municipal: campanhas sazonais, parcerias com influenciadores regionais, perfil oficial em plataformas de turismo | D8: Índice de Interesse Digital (Google Trends) | E8: Pearson Interesse Digital x Empregos Turismo = 0,83 (correlação forte) | F8: Alto | G8: Baixo | H8: P1
A9: Infraestrutura Urbana | B9: Baixa presença em plataformas (Booking, Airbnb) | C9: Programa de cadastramento assistido de pousadas e pequenos hotéis em plataformas digitais, com suporte técnico da prefeitura | D9: Empregos no Turismo / 1k hab | E9: Demanda digital de RO é ~5x menor que CF consistentemente desde 2010 | F9: Médio | G9: Baixo | H9: P1
A10: Infraestrutura Urbana | B10: Pontos turísticos sem manutenção/melhoria | C10: Revitalização da orla: iluminação, calçadão, mobiliário urbano e sinalização turística | D10: Empregos no Turismo / 1k hab; Arrecadação per capita | E10: VOC identificou "desenvolvimento das orlas" como direcionador prioritário do morador | F10: Alto | G10: Alto | H10: P2
A11: Infraestrutura Urbana | B11: Aumento esperado de furtos com retomada do turismo | C11: Reforço sazonal de policiamento (verão/feriados) em áreas turísticas e orla, com foco em furtos | D11: Furtos por 100k hab | E11: Pearson Furtos x Empregos Turismo = 0,93 — crescimento do turismo tende a elevar furtos | F11: Médio | G11: Médio | H11: P2
A12: Capital Humano | B12: Qualificação atrelada ao setor petróleo / êxodo pós-2014 | C12: Parceria com SENAC/SEBRAE para cursos de qualificação em hospitalidade, gastronomia, offshore e tecnologia. | D12: Empregos no Turismo / 1k hab | E12: Queda de 55% nos empregos formais de turismo entre 2013-2021 coincide com êxodo pós-crise da Petrobras | F12: Médio | G12: Médio | H12: P2
A13: Capital Humano | B13: Educação como subíndice mais fraco do IDHM | C13: Programa de educação técnica voltada a turismo e hospitalidade e tecnologia nas escolas municipais, em parceria com institutos federais | D13: IDHM — Educação | E13: IDHM Educação de RO = 0,733 (2021): menor dos 3 subíndices, gap de 0,14 vs Longevidade | F13: Alto | G13: Alto | H13: P3
A14: Oferta e Posicionamento | B14: Pouca diversidade de atrações / identidade fraca como destino | C14: Calendário cultural anual (eventos, festivais) para reduzir sazonalidade extrema (pico em janeiro) e criar identidade própria além do sol-e-praia | D14: Índice de Interesse Digital; Empregos no Turismo | E14: Sazonalidade extrema identificada no Google Trends: pico concentrado em janeiro (pode relacionar com o SESC verão) | F14: Médio | G14: Médio | H14: P3
A15: Monitoramento e Dados | B15: Sem monitoramento de ocupação hoteleira / KPIs | C15: Implementar painel público de indicadores de turismo (dashboard com ocupação, emprego no setor, arrecadação ISS turístico) | D15: Todos os indicadores de turismo | E15: Ausência de dados de ocupação e investimento em segurança foi limitação recorrente neste projeto | F15: Médio | G15: Baixo | H15: P2
A17: Prioridade: P1 = implementação imediata (baixo esforço/alto impacto) · P2 = curto-médio prazo · P3 = médio-longo prazo. Impacto e Esforço avaliados qualitativamente com base no escopo do projeto e nas evidências do Analyze.
A19: CICLOS PDSA — AÇÕES PRIORITÁRIAS (P1)
A20: Ação | B20: Plan (o que/meta) | D20: Do (como implementar) | F20: Study (métrica e predição) | H20: Act (decisão)
A21: Marketing Digital + Plataformas | B21: Aumentar o índice de Interesse Digital (Google Trends, soma hotel + pousada Rio das Ostras) de ~9 (média 2024-2025) para ≥15 em 12 meses — patamar observado entre 2014-2015. | D21: 1) Investir no perfil institucional da prefeitura no Instagram/TikTok com conteúdo da orla e pontos turísticos. 2) Programa de cadastramento assistido de pousadas no Booking/Airbnb (meta: +20 estabelecimentos em 6 meses). 3) Campanha sazonal pré-verão (out-dez) com parcerias de influenciadores regionais. | F21: Métrica: índice anual Google Trends (RO) e nº de empregos formais em hospedagem (RAIS). Predição: se o índice subir para ≥15, espera-se aumento de empregos no turismo/1k hab de 2,18 para ~3,0 (baseado na correlação histórica de 0,83). Prazo de avaliação: 12 meses. | H21: Se meta atingida → expandir campanha e formalizar como política permanente (Control). Se não atingida → revisar canais/mensagem antes de escalar investimento.
A22: Incentivo Fiscal para Hospedagem | B22: Atrair novos empreendimentos de hospedagem/lazer via ISS reduzido (24 meses), com meta de reverter a queda de % turismo sobre total de empregos (atualmente 0,8% em RO vs 3,0% em CF). | D22: 1) Lei municipal de incentivo fiscal temporário para hospedagem e alimentação. 2) Divulgação direcionada a investidores via associações comerciais e SEBRAE-RJ. 3) Simplificação do processo de licenciamento para novos estabelecimentos. | F22: Métrica: nº de novos CNPJs ativos em CNAE 5510/5590 (RAIS/Receita Federal) e % turismo/total de empregos. Predição: aumento de pelo menos 0,3 p.p. na participação do turismo no total de empregos formais em 24 meses. Prazo de avaliação: 24 meses. | H22: Se houver aumento de CNPJs/empregos → tornar incentivo permanente com critérios de renovação. Se não houver resposta → investigar barreiras não-fiscais (ex: infraestrutura, segurança).
A23: Plano Municipal de Turismo | B23: Formalizar plano com metas anuais públicas para: empregos no turismo/1k hab, arrecadação de ISS turístico e índice de interesse digital — partindo da base 2021 (2,18 / valor SICONFI / ~9). | D23: 1) Constituir grupo de trabalho intersetorial (turismo, fazenda, planejamento urbano). 2) Definir metas anuais alinhadas às demais ações (marketing, incentivo fiscal, revitalização). 3) Publicar plano e cronograma de revisão anual. | F23: Métrica: cumprimento das metas anuais definidas no plano (indicadores compostos). Predição: trajetória de recuperação de empregos no turismo/1k hab de 2,18 (2021) para ≥4,0 em 5 anos (retorno ao patamar de 2010), aproximando-se da tendência de CF. Prazo de avaliação: revisão anual, ciclo de 5 anos. | H23: Revisão anual do plano com base nos indicadores do Control — ajustar metas e ações conforme desvios.
A25: ROADMAP DE IMPLEMENTAÇÃO
A26: Horizonte | B26: Ações | E26: Indicadores a Monitorar (Control)
A27: Curto Prazo (0-6 meses) | B27: Marketing digital e redes sociais · Cadastramento de pousadas em plataformas · Início do desenho do Plano Municipal de Turismo | E27: Índice de Interesse Digital (Google Trends) · Nº de estabelecimentos cadastrados em plataformas
A28: Médio Prazo (6-18 meses) | B28: Lei de incentivo fiscal aprovada e em vigor · Reforço sazonal de policiamento na orla · Painel público de indicadores de turismo | E28: Empregos formais no turismo/1k hab · Furtos por 100k hab · Nº de novos CNPJs em hospedagem
A29: Longo Prazo (18+ meses) | B29: Revitalização da orla concluída · Programas de qualificação profissional em operação · Calendário cultural anual estabelecido | E29: PIB per capita · IDHM Educação · % empregos turismo/total · Arrecadação per capita
A31: Nota: A categoria "Conjuntura Econômica" (crise do setor petrolífero) identificada no Ishikawa não gerou ações neste plano por estar fora do controle municipal. As ações acima concentram-se nas 5 categorias acionáveis (Gestão e Planejamento, Monitoramento e Dados, Capital Humano, Infraestrutura Urbana e Oferta e Posicionamento), priorizando alavancas com maior respaldo estatístico do Analyze.
